ssh_exchange_identification: Connection closed by remote host
Traceback (most recent call last):
  File "/home/yl254115/miniconda3/lib/python3.7/site-packages/mne/externals/h5io/_h5io.py", line 112, in write_hdf5
    use_json=use_json)
  File "/home/yl254115/miniconda3/lib/python3.7/site-packages/mne/externals/h5io/_h5io.py", line 155, in _triage_write
    where + '[%s]' % vi, cleanup_data=cleanup_data, slash=slash)
  File "/home/yl254115/miniconda3/lib/python3.7/site-packages/mne/externals/h5io/_h5io.py", line 155, in _triage_write
    where + '[%s]' % vi, cleanup_data=cleanup_data, slash=slash)
  File "/home/yl254115/miniconda3/lib/python3.7/site-packages/mne/externals/h5io/_h5io.py", line 148, in _triage_write
    where + '["%s"]' % key, cleanup_data=cleanup_data, slash=slash)
  File "/home/yl254115/miniconda3/lib/python3.7/site-packages/mne/externals/h5io/_h5io.py", line 178, in _triage_write
    _create_titled_dataset(root, key, 'ndarray', value)
  File "/home/yl254115/miniconda3/lib/python3.7/site-packages/mne/externals/h5io/_h5io.py", line 49, in _create_titled_dataset
    out = root.create_dataset(key, data=data, **comp_kw)
  File "/home/yl254115/miniconda3/lib/python3.7/site-packages/h5py/_hl/group.py", line 136, in create_dataset
    dsid = dataset.make_new_dset(self, shape, dtype, data, **kwds)
  File "/home/yl254115/miniconda3/lib/python3.7/site-packages/h5py/_hl/dataset.py", line 170, in make_new_dset
    dset_id.write(h5s.ALL, h5s.ALL, data)
  File "h5py/_objects.pyx", line 54, in h5py._objects.with_phil.wrapper
  File "h5py/_objects.pyx", line 55, in h5py._objects.with_phil.wrapper
  File "h5py/h5d.pyx", line 221, in h5py.h5d.DatasetID.write
  File "h5py/_proxy.pyx", line 132, in h5py._proxy.dset_rw
  File "h5py/_proxy.pyx", line 93, in h5py._proxy.H5PY_H5Dwrite
OSError: Can't write data (file write failed: time = Sun Feb 23 00:02:04 2020
, filename = '/var/tmp/pbs.797200.pbsserver/patient_487_micro_LPHG_ch_68-tfr.h5', file descriptor = 4, errno = 28, error message = 'No space left on device', buf = 0x7f69ea6ac040, total write size = 635215872, bytes this sub-write = 635215872, bytes actually written = 18446744073709551615, offset = 977252352)

During handling of the above exception, another exception occurred:

Traceback (most recent call last):
  File "/neurospin/unicog/protocols/intracranial/Syntax_with_Fried/Code/Main/generate_multichannel_spectrotemporal_epochs_micro.py", line 89, in <module>
    epochsTFR_channel.save(os.path.join(path2epochs, filename), overwrite=True)
  File "/home/yl254115/miniconda3/lib/python3.7/site-packages/mne/time_frequency/tfr.py", line 991, in save
    write_tfrs(fname, self, overwrite=overwrite)
  File "/home/yl254115/miniconda3/lib/python3.7/site-packages/mne/time_frequency/tfr.py", line 2271, in write_tfrs
    slash='replace')
  File "/home/yl254115/miniconda3/lib/python3.7/site-packages/mne/externals/h5io/_h5io.py", line 112, in write_hdf5
    use_json=use_json)
  File "h5py/_objects.pyx", line 54, in h5py._objects.with_phil.wrapper
  File "h5py/_objects.pyx", line 55, in h5py._objects.with_phil.wrapper
  File "/home/yl254115/miniconda3/lib/python3.7/site-packages/h5py/_hl/files.py", line 442, in __exit__
    self.close()
  File "/home/yl254115/miniconda3/lib/python3.7/site-packages/h5py/_hl/files.py", line 424, in close
    h5i.dec_ref(id_)
  File "h5py/_objects.pyx", line 54, in h5py._objects.with_phil.wrapper
  File "h5py/_objects.pyx", line 55, in h5py._objects.with_phil.wrapper
  File "h5py/h5i.pyx", line 150, in h5py.h5i.dec_ref
RuntimeError: Problems closing file (file write failed: time = Sun Feb 23 00:02:04 2020
, filename = '/var/tmp/pbs.797200.pbsserver/patient_487_micro_LPHG_ch_68-tfr.h5', file descriptor = 4, errno = 28, error message = 'No space left on device', buf = 0x564263115c30, total write size = 2048, bytes this sub-write = 2048, bytes actually written = 18446744073709551615, offset = 4096)
/var/spool/pbs/mom_priv/jobs/797200.pbsserver.SC: line 1: 375651 Segmentation fault      python /neurospin/unicog/protocols/intracranial/Syntax_with_Fried/Code